Workbook

Sheet Sector Board
B2: U.S. INVESTMENT ACCELERATOR
B3: Deal pipeline by sector · updates automatically from the Deal Tracker tab — enter and edit deals there
B6: Nuclear | E6: Gas | H6: Oil & Gas Midstream
B7: =IF(COUNTIF('Deal Tracker'!$C$2:$C$500,$B$6)=0,"No deals yet",COUNTIF('Deal Tracker'!$C$2:$C$500,$B$6)&IF(COUNTIF('Deal Tracker'!$C$2:$C$500,$B$6)=1," deal · "," deals · ")&IF(SUMIF('Deal Tracker'!$C$2:$C$500,$B$6,'Deal Tracker'!$D$2:$D$500)>=1000,"$"&TEXT(SUMIF('Deal Tracker'!$C$2:$C$500,$B$6,'Deal Tracker'!$D$2:$D$500)/1000,"#,##0.0")&"B","$"&TEXT(SUMIF('Deal Tracker'!$C$2:$C$500,$B$6,'Deal Tracker'!$D$2:$D$500),"#,##0")&"M")) -> 1 deal · $2.5B | E7: =IF(COUNTIF('Deal Tracker'!$C$2:$C$500,$E$6)=0,"No deals yet",COUNTIF('Deal Tracker'!$C$2:$C$500,$E$6)&IF(COUNTIF('Deal Tracker'!$C$2:$C$500,$E$6)=1," deal · "," deals · ")&IF(SUMIF('Deal Tracker'!$C$2:$C$500,$E$6,'Deal Tracker'!$D$2:$D$500)>=1000,"$"&TEXT(SUMIF('Deal Tracker'!$C$2:$C$500,$E$6,'Deal Tracker'!$D$2:$D$500)/1000,"#,##0.0")&"B","$"&TEXT(SUMIF('Deal Tracker'!$C$2:$C$500,$E$6,'Deal Tracker'!$D$2:$D$500),"#,##0")&"M")) -> No deals yet | H7: =IF(COUNTIF('Deal Tracker'!$C$2:$C$500,$H$6)=0,"No deals yet",COUNTIF('Deal Tracker'!$C$2:$C$500,$H$6)&IF(COUNTIF('Deal Tracker'!$C$2:$C$500,$H$6)=1," deal · "," deals · ")&IF(SUMIF('Deal Tracker'!$C$2:$C$500,$H$6,'Deal Tracker'!$D$2:$D$500)>=1000,"$"&TEXT(SUMIF('Deal Tracker'!$C$2:$C$500,$H$6,'Deal Tracker'!$D$2:$D$500)/1000,"#,##0.0")&"B","$"&TEXT(SUMIF('Deal Tracker'!$C$2:$C$500,$H$6,'Deal Tracker'!$D$2:$D$500),"#,##0")&"M")) -> No deals yet
B8: =IFERROR(INDEX(Calc!$C$2:$C$500,MATCH($B$6&"#"&1,Calc!$B$2:$B$500,0)),"") -> Example NuclearCo | C8: =IFERROR(INDEX(Calc!$D$2:$D$500,MATCH($B$6&"#"&1,Calc!$B$2:$B$500,0)),"") -> $2,500M | E8: =IFERROR(INDEX(Calc!$C$2:$C$500,MATCH($E$6&"#"&1,Calc!$B$2:$B$500,0)),"") | F8: =IFERROR(INDEX(Calc!$D$2:$D$500,MATCH($E$6&"#"&1,Calc!$B$2:$B$500,0)),"") | H8: =IFERROR(INDEX(Calc!$C$2:$C$500,MATCH($H$6&"#"&1,Calc!$B$2:$B$500,0)),"") | I8: =IFERROR(INDEX(Calc!$D$2:$D$500,MATCH($H$6&"#"&1,Calc!$B$2:$B$500,0)),"")
B9: =IFERROR(INDEX(Calc!$E$2:$E$500,MATCH($B$6&"#"&1,Calc!$B$2:$B$500,0)),"") -> DOE, NRC · Target: Nov 2026 | E9: =IFERROR(INDEX(Calc!$E$2:$E$500,MATCH($E$6&"#"&1,Calc!$B$2:$B$500,0)),"") | H9: =IFERROR(INDEX(Calc!$E$2:$E$500,MATCH($H$6&"#"&1,Calc!$B$2:$B$500,0)),"")
B10: =IFERROR(INDEX(Calc!$C$2:$C$500,MATCH($B$6&"#"&2,Calc!$B$2:$B$500,0)),"") | C10: =IFERROR(INDEX(Calc!$D$2:$D$500,MATCH($B$6&"#"&2,Calc!$B$2:$B$500,0)),"") | E10: =IFERROR(INDEX(Calc!$C$2:$C$500,MATCH($E$6&"#"&2,Calc!$B$2:$B$500,0)),"") | F10: =IFERROR(INDEX(Calc!$D$2:$D$500,MATCH($E$6&"#"&2,Calc!$B$2:$B$500,0)),"") | H10: =IFERROR(INDEX(Calc!$C$2:$C$500,MATCH($H$6&"#"&2,Calc!$B$2:$B$500,0)),"") | I10: =IFERROR(INDEX(Calc!$D$2:$D$500,MATCH($H$6&"#"&2,Calc!$B$2:$B$500,0)),"")
B11: =IFERROR(INDEX(Calc!$E$2:$E$500,MATCH($B$6&"#"&2,Calc!$B$2:$B$500,0)),"") | E11: =IFERROR(INDEX(Calc!$E$2:$E$500,MATCH($E$6&"#"&2,Calc!$B$2:$B$500,0)),"") | H11: =IFERROR(INDEX(Calc!$E$2:$E$500,MATCH($H$6&"#"&2,Calc!$B$2:$B$500,0)),"")
B12: =IFERROR(INDEX(Calc!$C$2:$C$500,MATCH($B$6&"#"&3,Calc!$B$2:$B$500,0)),"") | C12: =IFERROR(INDEX(Calc!$D$2:$D$500,MATCH($B$6&"#"&3,Calc!$B$2:$B$500,0)),"") | E12: =IFERROR(INDEX(Calc!$C$2:$C$500,MATCH($E$6&"#"&3,Calc!$B$2:$B$500,0)),"") | F12: =IFERROR(INDEX(Calc!$D$2:$D$500,MATCH($E$6&"#"&3,Calc!$B$2:$B$500,0)),"") | H12: =IFERROR(INDEX(Calc!$C$2:$C$500,MATCH($H$6&"#"&3,Calc!$B$2:$B$500,0)),"") | I12: =IFERROR(INDEX(Calc!$D$2:$D$500,MATCH($H$6&"#"&3,Calc!$B$2:$B$500,0)),"")
B13: =IFERROR(INDEX(Calc!$E$2:$E$500,MATCH($B$6&"#"&3,Calc!$B$2:$B$500,0)),"") | E13: =IFERROR(INDEX(Calc!$E$2:$E$500,MATCH($E$6&"#"&3,Calc!$B$2:$B$500,0)),"") | H13: =IFERROR(INDEX(Calc!$E$2:$E$500,MATCH($H$6&"#"&3,Calc!$B$2:$B$500,0)),"")
B14: =IFERROR(INDEX(Calc!$C$2:$C$500,MATCH($B$6&"#"&4,Calc!$B$2:$B$500,0)),"") | C14: =IFERROR(INDEX(Calc!$D$2:$D$500,MATCH($B$6&"#"&4,Calc!$B$2:$B$500,0)),"") | E14: =IFERROR(INDEX(Calc!$C$2:$C$500,MATCH($E$6&"#"&4,Calc!$B$2:$B$500,0)),"") | F14: =IFERROR(INDEX(Calc!$D$2:$D$500,MATCH($E$6&"#"&4,Calc!$B$2:$B$500,0)),"") | H14: =IFERROR(INDEX(Calc!$C$2:$C$500,MATCH($H$6&"#"&4,Calc!$B$2:$B$500,0)),"") | I14: =IFERROR(INDEX(Calc!$D$2:$D$500,MATCH($H$6&"#"&4,Calc!$B$2:$B$500,0)),"")
B15: =IFERROR(INDEX(Calc!$E$2:$E$500,MATCH($B$6&"#"&4,Calc!$B$2:$B$500,0)),"") | E15: =IFERROR(INDEX(Calc!$E$2:$E$500,MATCH($E$6&"#"&4,Calc!$B$2:$B$500,0)),"") | H15: =IFERROR(INDEX(Calc!$E$2:$E$500,MATCH($H$6&"#"&4,Calc!$B$2:$B$500,0)),"")
B16: =IFERROR(INDEX(Calc!$C$2:$C$500,MATCH($B$6&"#"&5,Calc!$B$2:$B$500,0)),"") | C16: =IFERROR(INDEX(Calc!$D$2:$D$500,MATCH($B$6&"#"&5,Calc!$B$2:$B$500,0)),"") | E16: =IFERROR(INDEX(Calc!$C$2:$C$500,MATCH($E$6&"#"&5,Calc!$B$2:$B$500,0)),"") | F16: =IFERROR(INDEX(Calc!$D$2:$D$500,MATCH($E$6&"#"&5,Calc!$B$2:$B$500,0)),"") | H16: =IFERROR(INDEX(Calc!$C$2:$C$500,MATCH($H$6&"#"&5,Calc!$B$2:$B$500,0)),"") | I16: =IFERROR(INDEX(Calc!$D$2:$D$500,MATCH($H$6&"#"&5,Calc!$B$2:$B$500,0)),"")
B17: =IFERROR(INDEX(Calc!$E$2:$E$500,MATCH($B$6&"#"&5,Calc!$B$2:$B$500,0)),"") | E17: =IFERROR(INDEX(Calc!$E$2:$E$500,MATCH($E$6&"#"&5,Calc!$B$2:$B$500,0)),"") | H17: =IFERROR(INDEX(Calc!$E$2:$E$500,MATCH($H$6&"#"&5,Calc!$B$2:$B$500,0)),"")
B18: =IFERROR(INDEX(Calc!$C$2:$C$500,MATCH($B$6&"#"&6,Calc!$B$2:$B$500,0)),"") | C18: =IFERROR(INDEX(Calc!$D$2:$D$500,MATCH($B$6&"#"&6,Calc!$B$2:$B$500,0)),"") | E18: =IFERROR(INDEX(Calc!$C$2:$C$500,MATCH($E$6&"#"&6,Calc!$B$2:$B$500,0)),"") | F18: =IFERROR(INDEX(Calc!$D$2:$D$500,MATCH($E$6&"#"&6,Calc!$B$2:$B$500,0)),"") | H18: =IFERROR(INDEX(Calc!$C$2:$C$500,MATCH($H$6&"#"&6,Calc!$B$2:$B$500,0)),"") | I18: =IFERROR(INDEX(Calc!$D$2:$D$500,MATCH($H$6&"#"&6,Calc!$B$2:$B$500,0)),"")
B19: =IFERROR(INDEX(Calc!$E$2:$E$500,MATCH($B$6&"#"&6,Calc!$B$2:$B$500,0)),"") | E19: =IFERROR(INDEX(Calc!$E$2:$E$500,MATCH($E$6&"#"&6,Calc!$B$2:$B$500,0)),"") | H19: =IFERROR(INDEX(Calc!$E$2:$E$500,MATCH($H$6&"#"&6,Calc!$B$2:$B$500,0)),"")
B20: =IF(COUNTIF('Deal Tracker'!$C$2:$C$500,$B$6)>6,"+"&(COUNTIF('Deal Tracker'!$C$2:$C$500,$B$6)-6)&" more — see Deal Tracker","") | E20: =IF(COUNTIF('Deal Tracker'!$C$2:$C$500,$E$6)>6,"+"&(COUNTIF('Deal Tracker'!$C$2:$C$500,$E$6)-6)&" more — see Deal Tracker","") | H20: =IF(COUNTIF('Deal Tracker'!$C$2:$C$500,$H$6)>6,"+"&(COUNTIF('Deal Tracker'!$C$2:$C$500,$H$6)-6)&" more — see Deal Tracker","")
B23: Ships | E23: Minerals & Metals | H23: Pharma
B24: =IF(COUNTIF('Deal Tracker'!$C$2:$C$500,$B$23)=0,"No deals yet",COUNTIF('Deal Tracker'!$C$2:$C$500,$B$23)&IF(COUNTIF('Deal Tracker'!$C$2:$C$500,$B$23)=1," deal · "," deals · ")&IF(SUMIF('Deal Tracker'!$C$2:$C$500,$B$23,'Deal Tracker'!$D$2:$D$500)>=1000,"$"&TEXT(SUMIF('Deal Tracker'!$C$2:$C$500,$B$23,'Deal Tracker'!$D$2:$D$500)/1000,"#,##0.0")&"B","$"&TEXT(SUMIF('Deal Tracker'!$C$2:$C$500,$B$23,'Deal Tracker'!$D$2:$D$500),"#,##0")&"M")) -> 1 deal · $800M | E24: =IF(COUNTIF('Deal Tracker'!$C$2:$C$500,$E$23)=0,"No deals yet",COUNTIF('Deal Tracker'!$C$2:$C$500,$E$23)&IF(COUNTIF('Deal Tracker'!$C$2:$C$500,$E$23)=1," deal · "," deals · ")&IF(SUMIF('Deal Tracker'!$C$2:$C$500,$E$23,'Deal Tracker'!$D$2:$D$500)>=1000,"$"&TEXT(SUMIF('Deal Tracker'!$C$2:$C$500,$E$23,'Deal Tracker'!$D$2:$D$500)/1000,"#,##0.0")&"B","$"&TEXT(SUMIF('Deal Tracker'!$C$2:$C$500,$E$23,'Deal Tracker'!$D$2:$D$500),"#,##0")&"M")) -> No deals yet | H24: =IF(COUNTIF('Deal Tracker'!$C$2:$C$500,$H$23)=0,"No deals yet",COUNTIF('Deal Tracker'!$C$2:$C$500,$H$23)&IF(COUNTIF('Deal Tracker'!$C$2:$C$500,$H$23)=1," deal · "," deals · ")&IF(SUMIF('Deal Tracker'!$C$2:$C$500,$H$23,'Deal Tracker'!$D$2:$D$500)>=1000,"$"&TEXT(SUMIF('Deal Tracker'!$C$2:$C$500,$H$23,'Deal Tracker'!$D$2:$D$500)/1000,"#,##0.0")&"B","$"&TEXT(SUMIF('Deal Tracker'!$C$2:$C$500,$H$23,'Deal Tracker'!$D$2:$D$500),"#,##0")&"M")) -> No deals yet
B25: =IFERROR(INDEX(Calc!$C$2:$C$500,MATCH($B$23&"#"&1,Calc!$B$2:$B$500,0)),"") -> Example ShipCo | C25: =IFERROR(INDEX(Calc!$D$2:$D$500,MATCH($B$23&"#"&1,Calc!$B$2:$B$500,0)),"") -> $800M | E25: =IFERROR(INDEX(Calc!$C$2:$C$500,MATCH($E$23&"#"&1,Calc!$B$2:$B$500,0)),"") | F25: =IFERROR(INDEX(Calc!$D$2:$D$500,MATCH($E$23&"#"&1,Calc!$B$2:$B$500,0)),"") | H25: =IFERROR(INDEX(Calc!$C$2:$C$500,MATCH($H$23&"#"&1,Calc!$B$2:$B$500,0)),"") | I25: =IFERROR(INDEX(Calc!$D$2:$D$500,MATCH($H$23&"#"&1,Calc!$B$2:$B$500,0)),"")
B26: =IFERROR(INDEX(Calc!$E$2:$E$500,MATCH($B$23&"#"&1,Calc!$B$2:$B$500,0)),"") -> DOW · Target: Feb 2027 | E26: =IFERROR(INDEX(Calc!$E$2:$E$500,MATCH($E$23&"#"&1,Calc!$B$2:$B$500,0)),"") | H26: =IFERROR(INDEX(Calc!$E$2:$E$500,MATCH($H$23&"#"&1,Calc!$B$2:$B$500,0)),"")
B27: =IFERROR(INDEX(Calc!$C$2:$C$500,MATCH($B$23&"#"&2,Calc!$B$2:$B$500,0)),"") | C27: =IFERROR(INDEX(Calc!$D$2:$D$500,MATCH($B$23&"#"&2,Calc!$B$2:$B$500,0)),"") | E27: =IFERROR(INDEX(Calc!$C$2:$C$500,MATCH($E$23&"#"&2,Calc!$B$2:$B$500,0)),"") | F27: =IFERROR(INDEX(Calc!$D$2:$D$500,MATCH($E$23&"#"&2,Calc!$B$2:$B$500,0)),"") | H27: =IFERROR(INDEX(Calc!$C$2:$C$500,MATCH($H$23&"#"&2,Calc!$B$2:$B$500,0)),"") | I27: =IFERROR(INDEX(Calc!$D$2:$D$500,MATCH($H$23&"#"&2,Calc!$B$2:$B$500,0)),"")
B28: =IFERROR(INDEX(Calc!$E$2:$E$500,MATCH($B$23&"#"&2,Calc!$B$2:$B$500,0)),"") | E28: =IFERROR(INDEX(Calc!$E$2:$E$500,MATCH($E$23&"#"&2,Calc!$B$2:$B$500,0)),"") | H28: =IFERROR(INDEX(Calc!$E$2:$E$500,MATCH($H$23&"#"&2,Calc!$B$2:$B$500,0)),"")
B29: =IFERROR(INDEX(Calc!$C$2:$C$500,MATCH($B$23&"#"&3,Calc!$B$2:$B$500,0)),"") | C29: =IFERROR(INDEX(Calc!$D$2:$D$500,MATCH($B$23&"#"&3,Calc!$B$2:$B$500,0)),"") | E29: =IFERROR(INDEX(Calc!$C$2:$C$500,MATCH($E$23&"#"&3,Calc!$B$2:$B$500,0)),"") | F29: =IFERROR(INDEX(Calc!$D$2:$D$500,MATCH($E$23&"#"&3,Calc!$B$2:$B$500,0)),"") | H29: =IFERROR(INDEX(Calc!$C$2:$C$500,MATCH($H$23&"#"&3,Calc!$B$2:$B$500,0)),"") | I29: =IFERROR(INDEX(Calc!$D$2:$D$500,MATCH($H$23&"#"&3,Calc!$B$2:$B$500,0)),"")
B30: =IFERROR(INDEX(Calc!$E$2:$E$500,MATCH($B$23&"#"&3,Calc!$B$2:$B$500,0)),"") | E30: =IFERROR(INDEX(Calc!$E$2:$E$500,MATCH($E$23&"#"&3,Calc!$B$2:$B$500,0)),"") | H30: =IFERROR(INDEX(Calc!$E$2:$E$500,MATCH($H$23&"#"&3,Calc!$B$2:$B$500,0)),"")
B31: =IFERROR(INDEX(Calc!$C$2:$C$500,MATCH($B$23&"#"&4,Calc!$B$2:$B$500,0)),"") | C31: =IFERROR(INDEX(Calc!$D$2:$D$500,MATCH($B$23&"#"&4,Calc!$B$2:$B$500,0)),"") | E31: =IFERROR(INDEX(Calc!$C$2:$C$500,MATCH($E$23&"#"&4,Calc!$B$2:$B$500,0)),"") | F31: =IFERROR(INDEX(Calc!$D$2:$D$500,MATCH($E$23&"#"&4,Calc!$B$2:$B$500,0)),"") | H31: =IFERROR(INDEX(Calc!$C$2:$C$500,MATCH($H$23&"#"&4,Calc!$B$2:$B$500,0)),"") | I31: =IFERROR(INDEX(Calc!$D$2:$D$500,MATCH($H$23&"#"&4,Calc!$B$2:$B$500,0)),"")
B32: =IFERROR(INDEX(Calc!$E$2:$E$500,MATCH($B$23&"#"&4,Calc!$B$2:$B$500,0)),"") | E32: =IFERROR(INDEX(Calc!$E$2:$E$500,MATCH($E$23&"#"&4,Calc!$B$2:$B$500,0)),"") | H32: =IFERROR(INDEX(Calc!$E$2:$E$500,MATCH($H$23&"#"&4,Calc!$B$2:$B$500,0)),"")
B33: =IFERROR(INDEX(Calc!$C$2:$C$500,MATCH($B$23&"#"&5,Calc!$B$2:$B$500,0)),"") | C33: =IFERROR(INDEX(Calc!$D$2:$D$500,MATCH($B$23&"#"&5,Calc!$B$2:$B$500,0)),"") | E33: =IFERROR(INDEX(Calc!$C$2:$C$500,MATCH($E$23&"#"&5,Calc!$B$2:$B$500,0)),"") | F33: =IFERROR(INDEX(Calc!$D$2:$D$500,MATCH($E$23&"#"&5,Calc!$B$2:$B$500,0)),"") | H33: =IFERROR(INDEX(Calc!$C$2:$C$500,MATCH($H$23&"#"&5,Calc!$B$2:$B$500,0)),"") | I33: =IFERROR(INDEX(Calc!$D$2:$D$500,MATCH($H$23&"#"&5,Calc!$B$2:$B$500,0)),"")
B34: =IFERROR(INDEX(Calc!$E$2:$E$500,MATCH($B$23&"#"&5,Calc!$B$2:$B$500,0)),"") | E34: =IFERROR(INDEX(Calc!$E$2:$E$500,MATCH($E$23&"#"&5,Calc!$B$2:$B$500,0)),"") | H34: =IFERROR(INDEX(Calc!$E$2:$E$500,MATCH($H$23&"#"&5,Calc!$B$2:$B$500,0)),"")
B35: =IFERROR(INDEX(Calc!$C$2:$C$500,MATCH($B$23&"#"&6,Calc!$B$2:$B$500,0)),"") | C35: =IFERROR(INDEX(Calc!$D$2:$D$500,MATCH($B$23&"#"&6,Calc!$B$2:$B$500,0)),"") | E35: =IFERROR(INDEX(Calc!$C$2:$C$500,MATCH($E$23&"#"&6,Calc!$B$2:$B$500,0)),"") | F35: =IFERROR(INDEX(Calc!$D$2:$D$500,MATCH($E$23&"#"&6,Calc!$B$2:$B$500,0)),"") | H35: =IFERROR(INDEX(Calc!$C$2:$C$500,MATCH($H$23&"#"&6,Calc!$B$2:$B$500,0)),"") | I35: =IFERROR(INDEX(Calc!$D$2:$D$500,MATCH($H$23&"#"&6,Calc!$B$2:$B$500,0)),"")
B36: =IFERROR(INDEX(Calc!$E$2:$E$500,MATCH($B$23&"#"&6,Calc!$B$2:$B$500,0)),"") | E36: =IFERROR(INDEX(Calc!$E$2:$E$500,MATCH($E$23&"#"&6,Calc!$B$2:$B$500,0)),"") | H36: =IFERROR(INDEX(Calc!$E$2:$E$500,MATCH($H$23&"#"&6,Calc!$B$2:$B$500,0)),"")
B37: =IF(COUNTIF('Deal Tracker'!$C$2:$C$500,$B$23)>6,"+"&(COUNTIF('Deal Tracker'!$C$2:$C$500,$B$23)-6)&" more — see Deal Tracker","") | E37: =IF(COUNTIF('Deal Tracker'!$C$2:$C$500,$E$23)>6,"+"&(COUNTIF('Deal Tracker'!$C$2:$C$500,$E$23)-6)&" more — see Deal Tracker","") | H37: =IF(COUNTIF('Deal Tracker'!$C$2:$C$500,$H$23)>6,"+"&(COUNTIF('Deal Tracker'!$C$2:$C$500,$H$23)-6)&" more — see Deal Tracker","")
B40: Semiconductors | E40: Advanced Manufacturing | H40: Chemicals
B41: =IF(COUNTIF('Deal Tracker'!$C$2:$C$500,$B$40)=0,"No deals yet",COUNTIF('Deal Tracker'!$C$2:$C$500,$B$40)&IF(COUNTIF('Deal Tracker'!$C$2:$C$500,$B$40)=1," deal · "," deals · ")&IF(SUMIF('Deal Tracker'!$C$2:$C$500,$B$40,'Deal Tracker'!$D$2:$D$500)>=1000,"$"&TEXT(SUMIF('Deal Tracker'!$C$2:$C$500,$B$40,'Deal Tracker'!$D$2:$D$500)/1000,"#,##0.0")&"B","$"&TEXT(SUMIF('Deal Tracker'!$C$2:$C$500,$B$40,'Deal Tracker'!$D$2:$D$500),"#,##0")&"M")) -> 1 deal · $5.0B | E41: =IF(COUNTIF('Deal Tracker'!$C$2:$C$500,$E$40)=0,"No deals yet",COUNTIF('Deal Tracker'!$C$2:$C$500,$E$40)&IF(COUNTIF('Deal Tracker'!$C$2:$C$500,$E$40)=1," deal · "," deals · ")&IF(SUMIF('Deal Tracker'!$C$2:$C$500,$E$40,'Deal Tracker'!$D$2:$D$500)>=1000,"$"&TEXT(SUMIF('Deal Tracker'!$C$2:$C$500,$E$40,'Deal Tracker'!$D$2:$D$500)/1000,"#,##0.0")&"B","$"&TEXT(SUMIF('Deal Tracker'!$C$2:$C$500,$E$40,'Deal Tracker'!$D$2:$D$500),"#,##0")&"M")) -> No deals yet | H41: =IF(COUNTIF('Deal Tracker'!$C$2:$C$500,$H$40)=0,"No deals yet",COUNTIF('Deal Tracker'!$C$2:$C$500,$H$40)&IF(COUNTIF('Deal Tracker'!$C$2:$C$500,$H$40)=1," deal · "," deals · ")&IF(SUMIF('Deal Tracker'!$C$2:$C$500,$H$40,'Deal Tracker'!$D$2:$D$500)>=1000,"$"&TEXT(SUMIF('Deal Tracker'!$C$2:$C$500,$H$40,'Deal Tracker'!$D$2:$D$500)/1000,"#,##0.0")&"B","$"&TEXT(SUMIF('Deal Tracker'!$C$2:$C$500,$H$40,'Deal Tracker'!$D$2:$D$500),"#,##0")&"M")) -> No deals yet
B42: =IFERROR(INDEX(Calc!$C$2:$C$500,MATCH($B$40&"#"&1,Calc!$B$2:$B$500,0)),"") -> Example ChipCo | C42: =IFERROR(INDEX(Calc!$D$2:$D$500,MATCH($B$40&"#"&1,Calc!$B$2:$B$500,0)),"") -> $5,000M | E42: =IFERROR(INDEX(Calc!$C$2:$C$500,MATCH($E$40&"#"&1,Calc!$B$2:$B$500,0)),"") | F42: =IFERROR(INDEX(Calc!$D$2:$D$500,MATCH($E$40&"#"&1,Calc!$B$2:$B$500,0)),"") | H42: =IFERROR(INDEX(Calc!$C$2:$C$500,MATCH($H$40&"#"&1,Calc!$B$2:$B$500,0)),"") | I42: =IFERROR(INDEX(Calc!$D$2:$D$500,MATCH($H$40&"#"&1,Calc!$B$2:$B$500,0)),"")
B43: =IFERROR(INDEX(Calc!$E$2:$E$500,MATCH($B$40&"#"&1,Calc!$B$2:$B$500,0)),"") -> Target: Sep 2027 | E43: =IFERROR(INDEX(Calc!$E$2:$E$500,MATCH($E$40&"#"&1,Calc!$B$2:$B$500,0)),"") | H43: =IFERROR(INDEX(Calc!$E$2:$E$500,MATCH($H$40&"#"&1,Calc!$B$2:$B$500,0)),"")
B44: =IFERROR(INDEX(Calc!$C$2:$C$500,MATCH($B$40&"#"&2,Calc!$B$2:$B$500,0)),"") | C44: =IFERROR(INDEX(Calc!$D$2:$D$500,MATCH($B$40&"#"&2,Calc!$B$2:$B$500,0)),"") | E44: =IFERROR(INDEX(Calc!$C$2:$C$500,MATCH($E$40&"#"&2,Calc!$B$2:$B$500,0)),"") | F44: =IFERROR(INDEX(Calc!$D$2:$D$500,MATCH($E$40&"#"&2,Calc!$B$2:$B$500,0)),"") | H44: =IFERROR(INDEX(Calc!$C$2:$C$500,MATCH($H$40&"#"&2,Calc!$B$2:$B$500,0)),"") | I44: =IFERROR(INDEX(Calc!$D$2:$D$500,MATCH($H$40&"#"&2,Calc!$B$2:$B$500,0)),"")
B45: =IFERROR(INDEX(Calc!$E$2:$E$500,MATCH($B$40&"#"&2,Calc!$B$2:$B$500,0)),"") | E45: =IFERROR(INDEX(Calc!$E$2:$E$500,MATCH($E$40&"#"&2,Calc!$B$2:$B$500,0)),"") | H45: =IFERROR(INDEX(Calc!$E$2:$E$500,MATCH($H$40&"#"&2,Calc!$B$2:$B$500,0)),"")
B46: =IFERROR(INDEX(Calc!$C$2:$C$500,MATCH($B$40&"#"&3,Calc!$B$2:$B$500,0)),"") | C46: =IFERROR(INDEX(Calc!$D$2:$D$500,MATCH($B$40&"#"&3,Calc!$B$2:$B$500,0)),"") | E46: =IFERROR(INDEX(Calc!$C$2:$C$500,MATCH($E$40&"#"&3,Calc!$B$2:$B$500,0)),"") | F46: =IFERROR(INDEX(Calc!$D$2:$D$500,MATCH($E$40&"#"&3,Calc!$B$2:$B$500,0)),"") | H46: =IFERROR(INDEX(Calc!$C$2:$C$500,MATCH($H$40&"#"&3,Calc!$B$2:$B$500,0)),"") | I46: =IFERROR(INDEX(Calc!$D$2:$D$500,MATCH($H$40&"#"&3,Calc!$B$2:$B$500,0)),"")
B47: =IFERROR(INDEX(Calc!$E$2:$E$500,MATCH($B$40&"#"&3,Calc!$B$2:$B$500,0)),"") | E47: =IFERROR(INDEX(Calc!$E$2:$E$500,MATCH($E$40&"#"&3,Calc!$B$2:$B$500,0)),"") | H47: =IFERROR(INDEX(Calc!$E$2:$E$500,MATCH($H$40&"#"&3,Calc!$B$2:$B$500,0)),"")
...

Sheet Deal Tracker
A1: Deal # | B1: Company Name | C1: Sector | D1: Deal Size ($M) | E1: Status | F1: Lead Agency | G1: Other Agencies | H1: Target Close | I1: Accelerator Lead | J1: Next Steps / Notes | K1: Last Updated
A2: 001 | B2: Example NuclearCo | C2: Nuclear | D2: 2500 | E2: Diligence | F2: DOE | G2: NRC | H2: 46341 | J2: EXAMPLE ROW — delete before use. Site review call w/ DOE next week | K2: 46232
A3: 002 | B3: Example ShipCo | C3: Ships | D3: 800 | E3: Agency Engagement | F3: DOW | H3: 46433 | J3: EXAMPLE ROW — delete before use. Awaiting DOW program office response | K3: 46232
A4: 003 | B4: Example ChipCo | C4: Semiconductors | D4: 5000 | E4: Under Review | H4: 46645 | J4: EXAMPLE ROW — delete before use. Initial materials received | K4: 46232

Sheet Dashboard
B1: DASHBOARD — PIPELINE SUMMARY
B2: Updates automatically from the Deal Tracker tab.
B4: ="TOTAL PIPELINE: "&COUNTA('Deal Tracker'!$C$2:$C$500)&IF(COUNTA('Deal Tracker'!$C$2:$C$500)=1," deal · "," deals · ")&IF(SUM('Deal Tracker'!$D$2:$D$500)>=1000,"$"&TEXT(SUM('Deal Tracker'!$D$2:$D$500)/1000,"#,##0.0")&"B","$"&TEXT(SUM('Deal Tracker'!$D$2:$D$500),"#,##0")&"M") -> TOTAL PIPELINE: 3 deals · $8.3B
B6: PIPELINE BY SECTOR | F6: PIPELINE BY STATUS | J6: DEALS BY LEAD AGENCY
B7: Sector | C7: # Deals | D7: Total ($M) | F7: Status | G7: # Deals | H7: Total ($M) | J7: Agency | K7: # Deals | L7: Total ($M)
B8: ='Reference Lists'!A5 -> Nuclear | C8: =COUNTIF('Deal Tracker'!$C$2:$C$500,$B8) -> 1 | D8: =SUMIF('Deal Tracker'!$C$2:$C$500,$B8,'Deal Tracker'!$D$2:$D$500) -> 2500 | F8: ='Reference Lists'!C5 -> Intake | G8: =COUNTIF('Deal Tracker'!$E$2:$E$500,$F8) -> 0 | H8: =SUMIF('Deal Tracker'!$E$2:$E$500,$F8,'Deal Tracker'!$D$2:$D$500) -> 0 | J8: =IF('Reference Lists'!F5="","",'Reference Lists'!F5) -> DOE | K8: =IF($J8="","",COUNTIF('Deal Tracker'!$F$2:$F$500,$J8)) -> 1 | L8: =IF($J8="","",SUMIF('Deal Tracker'!$F$2:$F$500,$J8,'Deal Tracker'!$D$2:$D$500)) -> 2500
B9: ='Reference Lists'!A6 -> Gas | C9: =COUNTIF('Deal Tracker'!$C$2:$C$500,$B9) -> 0 | D9: =SUMIF('Deal Tracker'!$C$2:$C$500,$B9,'Deal Tracker'!$D$2:$D$500) -> 0 | F9: ='Reference Lists'!C6 -> Under Review | G9: =COUNTIF('Deal Tracker'!$E$2:$E$500,$F9) -> 1 | H9: =SUMIF('Deal Tracker'!$E$2:$E$500,$F9,'Deal Tracker'!$D$2:$D$500) -> 5000 | J9: =IF('Reference Lists'!F6="","",'Reference Lists'!F6) -> DOW | K9: =IF($J9="","",COUNTIF('Deal Tracker'!$F$2:$F$500,$J9)) -> 1 | L9: =IF($J9="","",SUMIF('Deal Tracker'!$F$2:$F$500,$J9,'Deal Tracker'!$D$2:$D$500)) -> 800
B10: ='Reference Lists'!A7 -> Oil & Gas Midstream | C10: =COUNTIF('Deal Tracker'!$C$2:$C$500,$B10) -> 0 | D10: =SUMIF('Deal Tracker'!$C$2:$C$500,$B10,'Deal Tracker'!$D$2:$D$500) -> 0 | F10: ='Reference Lists'!C7 -> Agency Engagement | G10: =COUNTIF('Deal Tracker'!$E$2:$E$500,$F10) -> 1 | H10: =SUMIF('Deal Tracker'!$E$2:$E$500,$F10,'Deal Tracker'!$D$2:$D$500) -> 800 | J10: =IF('Reference Lists'!F7="","",'Reference Lists'!F7) | K10: =IF($J10="","",COUNTIF('Deal Tracker'!$F$2:$F$500,$J10)) | L10: =IF($J10="","",SUMIF('Deal Tracker'!$F$2:$F$500,$J10,'Deal Tracker'!$D$2:$D$500))
B11: ='Reference Lists'!A8 -> Ships | C11: =COUNTIF('Deal Tracker'!$C$2:$C$500,$B11) -> 1 | D11: =SUMIF('Deal Tracker'!$C$2:$C$500,$B11,'Deal Tracker'!$D$2:$D$500) -> 800 | F11: ='Reference Lists'!C8 -> Diligence | G11: =COUNTIF('Deal Tracker'!$E$2:$E$500,$F11) -> 1 | H11: =SUMIF('Deal Tracker'!$E$2:$E$500,$F11,'Deal Tracker'!$D$2:$D$500) -> 2500 | J11: =IF('Reference Lists'!F8="","",'Reference Lists'!F8) | K11: =IF($J11="","",COUNTIF('Deal Tracker'!$F$2:$F$500,$J11)) | L11: =IF($J11="","",SUMIF('Deal Tracker'!$F$2:$F$500,$J11,'Deal Tracker'!$D$2:$D$500))
B12: ='Reference Lists'!A9 -> Minerals & Metals | C12: =COUNTIF('Deal Tracker'!$C$2:$C$500,$B12) -> 0 | D12: =SUMIF('Deal Tracker'!$C$2:$C$500,$B12,'Deal Tracker'!$D$2:$D$500) -> 0 | F12: ='Reference Lists'!C9 -> Negotiating Terms | G12: =COUNTIF('Deal Tracker'!$E$2:$E$500,$F12) -> 0 | H12: =SUMIF('Deal Tracker'!$E$2:$E$500,$F12,'Deal Tracker'!$D$2:$D$500) -> 0 | J12: =IF('Reference Lists'!F9="","",'Reference Lists'!F9) | K12: =IF($J12="","",COUNTIF('Deal Tracker'!$F$2:$F$500,$J12)) | L12: =IF($J12="","",SUMIF('Deal Tracker'!$F$2:$F$500,$J12,'Deal Tracker'!$D$2:$D$500))
B13: ='Reference Lists'!A10 -> Pharma | C13: =COUNTIF('Deal Tracker'!$C$2:$C$500,$B13) -> 0 | D13: =SUMIF('Deal Tracker'!$C$2:$C$500,$B13,'Deal Tracker'!$D$2:$D$500) -> 0 | F13: ='Reference Lists'!C10 -> Committed / Announced | G13: =COUNTIF('Deal Tracker'!$E$2:$E$500,$F13) -> 0 | H13: =SUMIF('Deal Tracker'!$E$2:$E$500,$F13,'Deal Tracker'!$D$2:$D$500) -> 0 | J13: =IF('Reference Lists'!F10="","",'Reference Lists'!F10) | K13: =IF($J13="","",COUNTIF('Deal Tracker'!$F$2:$F$500,$J13)) | L13: =IF($J13="","",SUMIF('Deal Tracker'!$F$2:$F$500,$J13,'Deal Tracker'!$D$2:$D$500))
B14: ='Reference Lists'!A11 -> Semiconductors | C14: =COUNTIF('Deal Tracker'!$C$2:$C$500,$B14) -> 1 | D14: =SUMIF('Deal Tracker'!$C$2:$C$500,$B14,'Deal Tracker'!$D$2:$D$500) -> 5000 | F14: ='Reference Lists'!C11 -> Closed | G14: =COUNTIF('Deal Tracker'!$E$2:$E$500,$F14) -> 0 | H14: =SUMIF('Deal Tracker'!$E$2:$E$500,$F14,'Deal Tracker'!$D$2:$D$500) -> 0 | J14: =IF('Reference Lists'!F11="","",'Reference Lists'!F11) | K14: =IF($J14="","",COUNTIF('Deal Tracker'!$F$2:$F$500,$J14)) | L14: =IF($J14="","",SUMIF('Deal Tracker'!$F$2:$F$500,$J14,'Deal Tracker'!$D$2:$D$500))
B15: ='Reference Lists'!A12 -> Advanced Manufacturing | C15: =COUNTIF('Deal Tracker'!$C$2:$C$500,$B15) -> 0 | D15: =SUMIF('Deal Tracker'!$C$2:$C$500,$B15,'Deal Tracker'!$D$2:$D$500) -> 0 | F15: ='Reference Lists'!C12 -> On Hold | G15: =COUNTIF('Deal Tracker'!$E$2:$E$500,$F15) -> 0 | H15: =SUMIF('Deal Tracker'!$E$2:$E$500,$F15,'Deal Tracker'!$D$2:$D$500) -> 0 | J15: =IF('Reference Lists'!F12="","",'Reference Lists'!F12) | K15: =IF($J15="","",COUNTIF('Deal Tracker'!$F$2:$F$500,$J15)) | L15: =IF($J15="","",SUMIF('Deal Tracker'!$F$2:$F$500,$J15,'Deal Tracker'!$D$2:$D$500))
B16: ='Reference Lists'!A13 -> Chemicals | C16: =COUNTIF('Deal Tracker'!$C$2:$C$500,$B16) -> 0 | D16: =SUMIF('Deal Tracker'!$C$2:$C$500,$B16,'Deal Tracker'!$D$2:$D$500) -> 0 | F16: ='Reference Lists'!C13 -> Withdrawn | G16: =COUNTIF('Deal Tracker'!$E$2:$E$500,$F16) -> 0 | H16: =SUMIF('Deal Tracker'!$E$2:$E$500,$F16,'Deal Tracker'!$D$2:$D$500) -> 0 | J16: =IF('Reference Lists'!F13="","",'Reference Lists'!F13) | K16: =IF($J16="","",COUNTIF('Deal Tracker'!$F$2:$F$500,$J16)) | L16: =IF($J16="","",SUMIF('Deal Tracker'!$F$2:$F$500,$J16,'Deal Tracker'!$D$2:$D$500))
B17: Total | C17: =SUM(C8:C16) -> 3 | D17: =SUM(D8:D16) -> 8300 | F17: Total | G17: =SUM(G8:G16) -> 3 | H17: =SUM(H8:H16) -> 8300 | J17: =IF('Reference Lists'!F14="","",'Reference Lists'!F14) | K17: =IF($J17="","",COUNTIF('Deal Tracker'!$F$2:$F$500,$J17)) | L17: =IF($J17="","",SUMIF('Deal Tracker'!$F$2:$F$500,$J17,'Deal Tracker'!$D$2:$D$500))
J18: =IF('Reference Lists'!F15="","",'Reference Lists'!F15) | K18: =IF($J18="","",COUNTIF('Deal Tracker'!$F$2:$F$500,$J18)) | L18: =IF($J18="","",SUMIF('Deal Tracker'!$F$2:$F$500,$J18,'Deal Tracker'!$D$2:$D$500))
J19: =IF('Reference Lists'!F16="","",'Reference Lists'!F16) | K19: =IF($J19="","",COUNTIF('Deal Tracker'!$F$2:$F$500,$J19)) | L19: =IF($J19="","",SUMIF('Deal Tracker'!$F$2:$F$500,$J19,'Deal Tracker'!$D$2:$D$500))
J20: =IF('Reference Lists'!F17="","",'Reference Lists'!F17) | K20: =IF($J20="","",COUNTIF('Deal Tracker'!$F$2:$F$500,$J20)) | L20: =IF($J20="","",SUMIF('Deal Tracker'!$F$2:$F$500,$J20,'Deal Tracker'!$D$2:$D$500))
J21: =IF('Reference Lists'!F18="","",'Reference Lists'!F18) | K21: =IF($J21="","",COUNTIF('Deal Tracker'!$F$2:$F$500,$J21)) | L21: =IF($J21="","",SUMIF('Deal Tracker'!$F$2:$F$500,$J21,'Deal Tracker'!$D$2:$D$500))

Sheet Reference Lists
A1: REFERENCE LISTS
A2: These lists power the dropdowns on the Deal Tracker. Edit them to customize the template.
A4: SECTORS | C4: DEAL STATUSES | D4: DEFINITION | F4: AGENCIES | H4: SECTOR | I4: TYPICAL AGENCIES
A5: Nuclear | C5: Intake | D5: New deal, initial information gathering | F5: DOE | H5: =A5 -> Nuclear | I5: DOE
A6: Gas | C6: Under Review | D6: Accelerator evaluating the opportunity | F6: DOW | H6: =A6 -> Gas | I6: DOE
A7: Oil & Gas Midstream | C7: Agency Engagement | D7: Coordinating with the relevant agencies | H7: =A7 -> Oil & Gas Midstream | I7: DOE
A8: Ships | C8: Diligence | D8: Detailed review underway | H8: =A8 -> Ships | I8: DOW
A9: Minerals & Metals | C9: Negotiating Terms | D9: Structure and terms being negotiated | H9: =A9 -> Minerals & Metals
A10: Pharma | C10: Committed / Announced | D10: Deal agreed or publicly announced | H10: =A10 -> Pharma
A11: Semiconductors | C11: Closed | D11: Deal complete | H11: =A11 -> Semiconductors
A12: Advanced Manufacturing | C12: On Hold | D12: Paused | H12: =A12 -> Advanced Manufacturing
A13: Chemicals | C13: Withdrawn | D13: No longer proceeding | H13: =A13 -> Chemicals
F20: Add agencies in the blank slots above — they feed the Lead Agency dropdown automatically.
A22: HOW TO USE THIS TEMPLATE
A23: 1. Enter each deal as a row on the Deal Tracker tab. Sector, Status, and Lead Agency are dropdowns.
A24: 2. The Sector Board and Dashboard tabs fill in automatically — never type on those two tabs.
A25: 3. Each Sector Board card shows the company, deal size, agencies, and target close date.
A26: 4. Three EXAMPLE rows (gray italic) are on the Deal Tracker — delete them before entering real deals.
A27: 5. Add your agencies in the AGENCIES list above, and fill in the Sector → Typical Agencies map as you go.
A28: 6. Deal sizes are entered in $ millions (a $2.5B deal is entered as 2500).
A29: 7. Optional: add a logo via Insert > Pictures on the Sector Board — the top-right corner is kept clear for it.

Sheet Calc
A1: Seq | B1: Key | C1: Company | D1: Size | E1: Detail | F1: Agencies | G1: Target
A2: =IF('Deal Tracker'!C2="","",COUNTIF('Deal Tracker'!$C$2:C2,'Deal Tracker'!C2)) -> 1 | B2: =IF(A2="","",'Deal Tracker'!C2&"#"&A2) -> Nuclear#1 | C2: =IF('Deal Tracker'!B2="","",'Deal Tracker'!B2) -> Example NuclearCo | D2: =IF('Deal Tracker'!B2="","",IF('Deal Tracker'!D2="","TBD","$"&TEXT('Deal Tracker'!D2,"#,##0")&"M")) -> $2,500M | E2: =IF('Deal Tracker'!B2="","",IF(AND(F2="",G2=""),"",F2&IF(OR(F2="",G2=""),""," · ")&G2)) -> DOE, NRC · Target: Nov 2026 | F2: =IF('Deal Tracker'!F2="",IF('Deal Tracker'!G2="","",'Deal Tracker'!G2),'Deal Tracker'!F2&IF('Deal Tracker'!G2="","",", "&'Deal Tracker'!G2)) -> DOE, NRC | G2: =IF('Deal Tracker'!H2="","","Target: "&TEXT('Deal Tracker'!H2,"mmm yyyy")) -> Target: Nov 2026
A3: =IF('Deal Tracker'!C3="","",COUNTIF('Deal Tracker'!$C$2:C3,'Deal Tracker'!C3)) -> 1 | B3: =IF(A3="","",'Deal Tracker'!C3&"#"&A3) -> Ships#1 | C3: =IF('Deal Tracker'!B3="","",'Deal Tracker'!B3) -> Example ShipCo | D3: =IF('Deal Tracker'!B3="","",IF('Deal Tracker'!D3="","TBD","$"&TEXT('Deal Tracker'!D3,"#,##0")&"M")) -> $800M | E3: =IF('Deal Tracker'!B3="","",IF(AND(F3="",G3=""),"",F3&IF(OR(F3="",G3=""),""," · ")&G3)) -> DOW · Target: Feb 2027 | F3: =IF('Deal Tracker'!F3="",IF('Deal Tracker'!G3="","",'Deal Tracker'!G3),'Deal Tracker'!F3&IF('Deal Tracker'!G3="","",", "&'Deal Tracker'!G3)) -> DOW | G3: =IF('Deal Tracker'!H3="","","Target: "&TEXT('Deal Tracker'!H3,"mmm yyyy")) -> Target: Feb 2027
A4: =IF('Deal Tracker'!C4="","",COUNTIF('Deal Tracker'!$C$2:C4,'Deal Tracker'!C4)) -> 1 | B4: =IF(A4="","",'Deal Tracker'!C4&"#"&A4) -> Semiconductors#1 | C4: =IF('Deal Tracker'!B4="","",'Deal Tracker'!B4) -> Example ChipCo | D4: =IF('Deal Tracker'!B4="","",IF('Deal Tracker'!D4="","TBD","$"&TEXT('Deal Tracker'!D4,"#,##0")&"M")) -> $5,000M | E4: =IF('Deal Tracker'!B4="","",IF(AND(F4="",G4=""),"",F4&IF(OR(F4="",G4=""),""," · ")&G4)) -> Target: Sep 2027 | F4: =IF('Deal Tracker'!F4="",IF('Deal Tracker'!G4="","",'Deal Tracker'!G4),'Deal Tracker'!F4&IF('Deal Tracker'!G4="","",", "&'Deal Tracker'!G4)) | G4: =IF('Deal Tracker'!H4="","","Target: "&TEXT('Deal Tracker'!H4,"mmm yyyy")) -> Target: Sep 2027
A5: =IF('Deal Tracker'!C5="","",COUNTIF('Deal Tracker'!$C$2:C5,'Deal Tracker'!C5)) | B5: =IF(A5="","",'Deal Tracker'!C5&"#"&A5) | C5: =IF('Deal Tracker'!B5="","",'Deal Tracker'!B5) | D5: =IF('Deal Tracker'!B5="","",IF('Deal Tracker'!D5="","TBD","$"&TEXT('Deal Tracker'!D5,"#,##0")&"M")) | E5: =IF('Deal Tracker'!B5="","",IF(AND(F5="",G5=""),"",F5&IF(OR(F5="",G5=""),""," · ")&G5)) | F5: =IF('Deal Tracker'!F5="",IF('Deal Tracker'!G5="","",'Deal Tracker'!G5),'Deal Tracker'!F5&IF('Deal Tracker'!G5="","",", "&'Deal Tracker'!G5)) | G5: =IF('Deal Tracker'!H5="","","Target: "&TEXT('Deal Tracker'!H5,"mmm yyyy"))
A6: =IF('Deal Tracker'!C6="","",COUNTIF('Deal Tracker'!$C$2:C6,'Deal Tracker'!C6)) | B6: =IF(A6="","",'Deal Tracker'!C6&"#"&A6) | C6: =IF('Deal Tracker'!B6="","",'Deal Tracker'!B6) | D6: =IF('Deal Tracker'!B6="","",IF('Deal Tracker'!D6="","TBD","$"&TEXT('Deal Tracker'!D6,"#,##0")&"M")) | E6: =IF('Deal Tracker'!B6="","",IF(AND(F6="",G6=""),"",F6&IF(OR(F6="",G6=""),""," · ")&G6)) | F6: =IF('Deal Tracker'!F6="",IF('Deal Tracker'!G6="","",'Deal Tracker'!G6),'Deal Tracker'!F6&IF('Deal Tracker'!G6="","",", "&'Deal Tracker'!G6)) | G6: =IF('Deal Tracker'!H6="","","Target: "&TEXT('Deal Tracker'!H6,"mmm yyyy"))
A7: =IF('Deal Tracker'!C7="","",COUNTIF('Deal Tracker'!$C$2:C7,'Deal Tracker'!C7)) | B7: =IF(A7="","",'Deal Tracker'!C7&"#"&A7) | C7: =IF('Deal Tracker'!B7="","",'Deal Tracker'!B7) | D7: =IF('Deal Tracker'!B7="","",IF('Deal Tracker'!D7="","TBD","$"&TEXT('Deal Tracker'!D7,"#,##0")&"M")) | E7: =IF('Deal Tracker'!B7="","",IF(AND(F7="",G7=""),"",F7&IF(OR(F7="",G7=""),""," · ")&G7)) | F7: =IF('Deal Tracker'!F7="",IF('Deal Tracker'!G7="","",'Deal Tracker'!G7),'Deal Tracker'!F7&IF('Deal Tracker'!G7="","",", "&'Deal Tracker'!G7)) | G7: =IF('Deal Tracker'!H7="","","Target: "&TEXT('Deal Tracker'!H7,"mmm yyyy"))
A8: =IF('Deal Tracker'!C8="","",COUNTIF('Deal Tracker'!$C$2:C8,'Deal Tracker'!C8)) | B8: =IF(A8="","",'Deal Tracker'!C8&"#"&A8) | C8: =IF('Deal Tracker'!B8="","",'Deal Tracker'!B8) | D8: =IF('Deal Tracker'!B8="","",IF('Deal Tracker'!D8="","TBD","$"&TEXT('Deal Tracker'!D8,"#,##0")&"M")) | E8: =IF('Deal Tracker'!B8="","",IF(AND(F8="",G8=""),"",F8&IF(OR(F8="",G8=""),""," · ")&G8)) | F8: =IF('Deal Tracker'!F8="",IF('Deal Tracker'!G8="","",'Deal Tracker'!G8),'Deal Tracker'!F8&IF('Deal Tracker'!G8="","",", "&'Deal Tracker'!G8)) | G8: =IF('Deal Tracker'!H8="","","Target: "&TEXT('Deal Tracker'!H8,"mmm yyyy"))
A9: =IF('Deal Tracker'!C9="","",COUNTIF('Deal Tracker'!$C$2:C9,'Deal Tracker'!C9)) | B9: =IF(A9="","",'Deal Tracker'!C9&"#"&A9) | C9: =IF('Deal Tracker'!B9="","",'Deal Tracker'!B9) | D9: =IF('Deal Tracker'!B9="","",IF('Deal Tracker'!D9="","TBD","$"&TEXT('Deal Tracker'!D9,"#,##0")&"M")) | E9: =IF('Deal Tracker'!B9="","",IF(AND(F9="",G9=""),"",F9&IF(OR(F9="",G9=""),""," · ")&G9)) | F9: =IF('Deal Tracker'!F9="",IF('Deal Tracker'!G9="","",'Deal Tracker'!G9),'Deal Tracker'!F9&IF('Deal Tracker'!G9="","",", "&'Deal Tracker'!G9)) | G9: =IF('Deal Tracker'!H9="","","Target: "&TEXT('Deal Tracker'!H9,"mmm yyyy"))
A10: =IF('Deal Tracker'!C10="","",COUNTIF('Deal Tracker'!$C$2:C10,'Deal Tracker'!C10)) | B10: =IF(A10="","",'Deal Tracker'!C10&"#"&A10) | C10: =IF('Deal Tracker'!B10="","",'Deal Tracker'!B10) | D10: =IF('Deal Tracker'!B10="","",IF('Deal Tracker'!D10="","TBD","$"&TEXT('Deal Tracker'!D10,"#,##0")&"M")) | E10: =IF('Deal Tracker'!B10="","",IF(AND(F10="",G10=""),"",F10&IF(OR(F10="",G10=""),""," · ")&G10)) | F10: =IF('Deal Tracker'!F10="",IF('Deal Tracker'!G10="","",'Deal Tracker'!G10),'Deal Tracker'!F10&IF('Deal Tracker'!G10="","",", "&'Deal Tracker'!G10)) | G10: =IF('Deal Tracker'!H10="","","Target: "&TEXT('Deal Tracker'!H10,"mmm yyyy"))
A11: =IF('Deal Tracker'!C11="","",COUNTIF('Deal Tracker'!$C$2:C11,'Deal Tracker'!C11)) | B11: =IF(A11="","",'Deal Tracker'!C11&"#"&A11) | C11: =IF('Deal Tracker'!B11="","",'Deal Tracker'!B11) | D11: =IF('Deal Tracker'!B11="","",IF('Deal Tracker'!D11="","TBD","$"&TEXT('Deal Tracker'!D11,"#,##0")&"M")) | E11: =IF('Deal Tracker'!B11="","",IF(AND(F11="",G11=""),"",F11&IF(OR(F11="",G11=""),""," · ")&G11)) | F11: =IF('Deal Tracker'!F11="",IF('Deal Tracker'!G11="","",'Deal Tracker'!G11),'Deal Tracker'!F11&IF('Deal Tracker'!G11="","",", "&'Deal Tracker'!G11)) | G11: =IF('Deal Tracker'!H11="","","Target: "&TEXT('Deal Tracker'!H11,"mmm yyyy"))
A12: =IF('Deal Tracker'!C12="","",COUNTIF('Deal Tracker'!$C$2:C12,'Deal Tracker'!C12)) | B12: =IF(A12="","",'Deal Tracker'!C12&"#"&A12) | C12: =IF('Deal Tracker'!B12="","",'Deal Tracker'!B12) | D12: =IF('Deal Tracker'!B12="","",IF('Deal Tracker'!D12="","TBD","$"&TEXT('Deal Tracker'!D12,"#,##0")&"M")) | E12: =IF('Deal Tracker'!B12="","",IF(AND(F12="",G12=""),"",F12&IF(OR(F12="",G12=""),""," · ")&G12)) | F12: =IF('Deal Tracker'!F12="",IF('Deal Tracker'!G12="","",'Deal Tracker'!G12),'Deal Tracker'!F12&IF('Deal Tracker'!G12="","",", "&'Deal Tracker'!G12)) | G12: =IF('Deal Tracker'!H12="","","Target: "&TEXT('Deal Tracker'!H12,"mmm yyyy"))
A13: =IF('Deal Tracker'!C13="","",COUNTIF('Deal Tracker'!$C$2:C13,'Deal Tracker'!C13)) | B13: =IF(A13="","",'Deal Tracker'!C13&"#"&A13) | C13: =IF('Deal Tracker'!B13="","",'Deal Tracker'!B13) | D13: =IF('Deal Tracker'!B13="","",IF('Deal Tracker'!D13="","TBD","$"&TEXT('Deal Tracker'!D13,"#,##0")&"M")) | E13: =IF('Deal Tracker'!B13="","",IF(AND(F13="",G13=""),"",F13&IF(OR(F13="",G13=""),""," · ")&G13)) | F13: =IF('Deal Tracker'!F13="",IF('Deal Tracker'!G13="","",'Deal Tracker'!G13),'Deal Tracker'!F13&IF('Deal Tracker'!G13="","",", "&'Deal Tracker'!G13)) | G13: =IF('Deal Tracker'!H13="","","Target: "&TEXT('Deal Tracker'!H13,"mmm yyyy"))
... A500: =IF('Deal Tracker'!C500="","",COUNTIF('Deal Tracker'!$C$2:C500,'Deal Tracker'!C500)) | B500: =IF(A500="","",'Deal Tracker'!C500&"#"&A500) | C500: =IF('Deal Tracker'!B500="","",'Deal Tracker'!B500) | D500: =IF('Deal Tracker'!B500="","",IF('Deal Tracker'!D500="","TBD","$"&TEXT('Deal Tracker'!D500,"#,##0")&"M")) | E500: =IF('Deal Tracker'!B500="","",IF(AND(F500="",G500=""),"",F500&IF(OR(F500="",G500=""),""," · ")&G500)) | F500: =IF('Deal Tracker'!F500="",IF('Deal Tracker'!G500="","",'Deal Tracker'!G500),'Deal Tracker'!F500&IF('Deal Tracker'!G500="","",", "&'Deal Tracker'!G500)) | G500: =IF('Deal Tracker'!H500="","","Target: "&TEXT('Deal Tracker'!H500,"mmm yyyy"))
